Workbook

Sheet Read me
A1: Elective Capacity: Scenario and Strategy Model
A2: NHS Cheshire and Merseyside ICB (QYG). 12 core acute and specialist trusts, 18 months to September 2027
B4: What this model is for | C4: Phase 3 of this programme produced a single optimal allocation of a fixed budget across three capacity levers. That answer depends on seven parameters, four of which are analyst estimates rather than sourced figures. This model asks the question the optimiser cannot: given that uncertainty, which commitment should the ICB actually make, and what would have to be observed for that commitment to be wrong.
B5: What it is not | C5: It is not a forecast and it does not assign probabilities to the scenarios. Scenarios here are tests of plausibility, in the intuitive-logics tradition, not predictions.
B6: How to use it | C6: Start at Recommendation. Decision Analysis holds the objective weights in yellow cells. Change them and the strategy ordering recalculates. Early Warning lists the indicators to refresh monthly, and Results Grid holds the underlying numbers.
B7: Reading the colours | C7: Blue figures are inputs computed by the linear programme outside this workbook and cannot be reproduced by Excel formulas. Black figures are calculated live inside the workbook. Amber italics mark analyst judgement rather than computation. Yellow cells are for the user to change.
B8: Provenance | C8: All activity, workforce, bed and deprivation data is drawn from the project warehouse (NHS England RTT, DM01, KH03, Workforce Statistics, IMD 2019). Unit costs are from the National Cost Collection 2024/25 and the 2025/26 NHS Payment Scheme. Every parameter carries an evidence grade on the Driving Forces tab.
B9: The one figure with no source | C9: The diagnostic lever is priced using an assumed 1.75 diagnostic tests per unlocked pathway. No NHS dataset publishes this ratio. The scenario analysis shows the whole recommendation turns on it, so it is triangulated against observed data on the Diagnostic Triangulation tab and monitored as flag F2.
B10: Known limitation | C10: The linear programme has multiple equally optimal solutions whenever two levers are priced identically. Provider-level allocations are therefore not unique. Totals, constraint satisfaction, the equity figures and the delivery-risk figures are reliable. Each is pinned by a hierarchical solve that maximises volume, then equity within that, then minimises reliance on the weakest-evidenced levers within that. A specific provider-by-provider split is still not unique and must not be used as a distribution plan.
B12: Method basis | C12: Cairns, G. and Wright, G. (2018) Scenario Thinking, 2nd ed., Palgrave Macmillan. Ch.2 basic method, Ch.5 sum-of-ranks decision analysis, Ch.8 robust strategy and flags. Sminia, H. (2026) "From Scenario Thinking to Scenario Doing: Strategic Management as Wayfinding", Futures & Foresight Science 8:e70038. Sminia, H. (2022) The Strategic Manager, 3rd ed., Ch.7 for the institutional feasibility screen.

Sheet Driving forces
A1: Stages 2-4: Driving Forces and Their Plausible Range
A2: Environmental uncertainties the ICB does not control. Equity stringency is excluded deliberately. It is a policy choice the ICB does control, so it is modelled as a dimension of strategy instead.
A4: Cluster | B4: PESTEL | C4: What it is | D4: Low | E4: Base | F4: High | G4: Low outcome | H4: High outcome | I4: Evidence grade and basis
A5: Funding settlement | B5: Political / Economic | C5: Elective recovery funding envelope available to the ICB (18 months) | D5: 7500000 | E5: 15000000 | F5: 30000000 | G5: £7.5m — constrained settlement | H5: £30m — expanded recovery funding | I5: Grade 4. No ICB-level elective recovery budget is published at any level. The Phase 3 default of £15m was set as an illustrative, deliberately binding envelope, never as a sourced figure. Range spans half to double that anchor.
A6: Diagnostic conversion | B6: Technological | C6: Diagnostic tests required to unlock one completed RTT pathway | D6: 1.25 | E6: 1.75 | F6: 3.5 | G6: 1.25 — efficient conversion | H6: 3.50 — test-heavy pathways | I6: Grade 4. The single remaining unsourced figure in the Phase 3 cost model, flagged as such throughout. No NHS dataset publishes this ratio. It sets the unit cost of the diagnostic lever and therefore how much capacity a given budget buys through it. The upper bound is set at 3.50 deliberately: the diagnostic and treatment levers are indifferent at 3.34 tests per pathway (see tipping_points()), and a range that stopped short of that point would conceal the only decision in the model rather than test it. Three or more tests to reach a treatment decision is clinically ordinary on complex pathways, so the bound is plausible as well as convenient.
A7: Payment policy and cost base | B7: Political / Legal | C7: Unit cost of elective activity relative to NCC 2024/25 baseline | D7: 0.9 | E7: 1 | F7: 1.2 | G7: -10% — costs contained | H7: +20% — cost or policy inflation | I7: Grade 1. Unit costs are sourced from NCC 2024/25 and the 2025/26 NHS Payment Scheme. Graded low-uncertainty on provenance, but ranged anyway: the removal of the ERF marginal-rate mechanism for 2025/26 is direct evidence that payment policy does change materially between years.
A8: Backlog trajectory | B8: Social / Economic | C8: Over-52-week backlog to be cleared, relative to central forecast | D8: 0.9112 | E8: 1 | F8: 1.1466 | G8: p5 — backlog undershoots forecast | H8: p95 — backlog overshoots forecast | I8: Grade 2. Taken directly from the Phase 2 Monte Carlo waiting-list forecast: the ratio of the p5 and p95 ICB totals to the p50 total at horizon end (September 2027). Measured, not assumed.
A9: Independent-sector capacity | B9: Economic / Political | C9: Independent-sector headroom above current NHS-funded activity | D9: 0.2 | E9: 0.5 | F9: 0.8 | G9: +20% — sector at practical capacity | H9: +80% — sector scales readily | I9: Grade 4. Analyst assumption from Phase 3, chosen on the reasoning that the independent sector is more scalable short-term than NHS in-house capacity. No published measure of independent-sector spare elective capacity for this ICB exists.
A10: NHS productivity | B10: Technological / Social | C10: Achievable uplift in NHS in-house elective completions | D10: 0.05 | E10: 0.15 | F10: 0.25 | G10: +5% — productivity stalls | H10: +25% — sustained productivity gain | I10: Grade 3. Anchored on the Elective Recovery Fund's own national 10% activity increase target plus a buffer. Policy-anchored, but the achievable rate for these specific trusts is not published.
A12: Evidence grading rubric
A13: Grade 1 | B13: Sourced — published national dataset covering the current period (NCC 2024/25; NHS Payment Scheme 2025/26).
A14: Grade 2 | B14: Measured — derived from this warehouse's own observed data with a quantified interval attached (Phase 2 Monte Carlo forecast).
A15: Grade 3 | B15: Anchored estimate — extrapolated from warehouse data or from a stated national policy target, but not itself a published figure.
A16: Grade 4 | B16: Unsourced estimate — analyst judgement with no published source, or a quantity for which no public figure exists at any level.

Sheet Impact-uncertainty
A1: Stage 5: Impact / Uncertainty Matrix
A2: The impact axis is computed, not judged. It is the swing in breaches cleared when each driving force moves across its range with all others held at base. The uncertainty axis is the evidence grade. Criticality is the product of the two, normalised.
A4: Cluster | B4: Breaches cleared at low | C4: At base | D4: At high | E4: Swing (impact) | F4: Impact, normalised | G4: Uncertainty, normalised | H4: Criticality
A5: Funding settlement | B5: 30324.494 | C5: 60648.988 | D5: 121297.98 | E5: =ABS(D5-B5) -> 90973.483 | F5: =IF(MAX($E$5:$E$10)=0,0,E5/MAX($E$5:$E$10)) -> 1 | G5: 1 | H5: =F5*G5 -> 1
A6: Diagnostic conversion | B6: 84908.584 | C6: 60648.988 | D6: 31746.716 | E6: =ABS(D6-B6) -> 53161.868 | F6: =IF(MAX($E$5:$E$10)=0,0,E6/MAX($E$5:$E$10)) -> 0.58436664 | G6: 1 | H6: =F6*G6 -> 0.58436664
A7: Payment policy and cost base | B7: 67387.765 | C7: 60648.988 | D7: 50540.824 | E7: =ABS(D7-B7) -> 16846.941 | F7: =IF(MAX($E$5:$E$10)=0,0,E7/MAX($E$5:$E$10)) -> 0.18518519 | G7: 0 | H7: =F7*G7 -> 0
A8: Backlog trajectory | B8: 60648.988 | C8: 60648.988 | D8: 60648.988 | E8: =ABS(D8-B8) -> 0 | F8: =IF(MAX($E$5:$E$10)=0,0,E8/MAX($E$5:$E$10)) -> 0 | G8: 0.33333333 | H8: =F8*G8 -> 0
A9: Independent-sector capacity | B9: 60648.988 | C9: 60648.988 | D9: 60648.988 | E9: =ABS(D9-B9) -> 0 | F9: =IF(MAX($E$5:$E$10)=0,0,E9/MAX($E$5:$E$10)) -> 0 | G9: 1 | H9: =F9*G9 -> 0
A10: NHS productivity | B10: 60648.988 | C10: 60648.988 | D10: 60648.988 | E10: =ABS(D10-B10) -> 0 | F10: =IF(MAX($E$5:$E$10)=0,0,E10/MAX($E$5:$E$10)) -> 0 | G10: 0.66666667 | H10: =F10*G10 -> 0
A12: Selected scenario factors
A13: Factor A | B13: Funding settlement
A14: Factor B | B14: Diagnostic conversion
A16: The most important result on this tab
A17: Three of the six candidate driving forces move the outcome by nothing at all. Independent-sector scalability, NHS in-house productivity and the size of the backlog itself have zero effect on how many breaches the programme clears, at any funding level in scope. The reason is structural: no capacity ceiling binds until the envelope reaches £31.9m (independent sector), £69.7m (diagnostic) or £107.1m (in-house), all above the range under consideration. Within that range this is not a capacity-constrained problem at all. It is a money-constrained one. Three long-running debates are therefore not live decisions, and the scenario set does not spend effort on them.
A20: Anchor-stability check
A21: Cluster | B21: Swing at base anchor | C21: Swing at diagnostic-high anchor | D21: Criticality at base | E21: Criticality at alt | F21: State-dependent?
A22: Funding settlement | B22: 90973.483 | C22: 47620.074 | D22: 1 | E22: 0.89575622 | F22: No
A23: Diagnostic conversion | B23: 53161.868 | C23: 53161.868 | D23: 0.58436664 | E23: 1 | F23: No
A24: Payment policy and cost base | B24: 16846.941 | C24: 8818.5322 | D24: 0 | E24: 0 | F24: No
A25: Backlog trajectory | B25: 0 | C25: 0 | D25: 0 | E25: 0 | F25: No
A26: Independent-sector capacity | B26: 0 | C26: 3.6379788e-12 | D26: 0 | E26: 6.843211e-17 | F26: No
A27: NHS productivity | B27: 0 | C27: 0 | D27: 0 | E27: 0 | F27: No
A29: A one-at-a-time tornado is only valid at the point it is evaluated. The sweep was re-run from the far corner of the most critical driver to check that no force is being recorded as inert only because of where the analysis was anchored. None flipped.

Sheet Tipping points
A1: Where the Answer Becomes a Different Answer
A2: A sensitivity range says how far the outcome moves. A tipping point says where the optimal lever mix changes shape. Found by bisection on the spend mix.
A4: Cluster | B4: Base assumption | C4: Tipping point | D4: Finding
A5: Funding settlement | B5: n/a | C5: none in range | D5: No change in the optimal lever mix anywhere in the plausible range.
A6: Backlog trajectory | B6: n/a | C6: none in range | D6: No change in the optimal lever mix anywhere in the plausible range.
A7: Independent-sector capacity | B7: n/a | C7: none in range | D7: No change in the optimal lever mix anywhere in the plausible range.
A8: NHS productivity | B8: n/a | C8: none in range | D8: No change in the optimal lever mix anywhere in the plausible range.
A9: Diagnostic conversion | B9: 1.75 | C9: 3.342885 | D9: Optimal lever mix changes shape at 3.343 (base assumption 1.75).
A10: Payment policy and cost base | B10: n/a | C10: none in range | D10: No change in the optimal lever mix anywhere in the plausible range.
A12: Why this matters
A13: Exactly one parameter in the model has a tipping point inside its plausible range, and it is the one parameter with no published source. Below 3.34 diagnostic tests per unlocked pathway, diagnostics are the cheapest route to a cleared pathway and the programme should be diagnostic-led. Above it, the diagnostic lever is dominated and the programme should buy treatment capacity instead. The working assumption of 1.75 sits below the threshold, and observed data (see Diagnostic Triangulation) sits lower still. But the entire allocation rests on which side of 3.34 the true value falls.

Sheet Scenarios
A1: Stages 6-7: The Scenario Set
A2: Four scenarios framed from the extremes of Factors A and B, plus the central case carried as a reference baseline.
A4: Code | B4: Name | C4: Factor A: Funding settlement | D4: Factor B: Diagnostic conversion | E4: Funding envelope | F4: Tests per pathway
A5: A1B1 | B5: Lean money, efficient diagnostics | C5: £7.5m — constrained settlement | D5: 1.25 — efficient conversion | E5: 7500000 | F5: 1.25
A6: A1B2 | B6: Lean money, test-heavy pathways | C6: £7.5m — constrained settlement | D6: 3.50 — test-heavy pathways | E6: 7500000 | F6: 3.5
A7: A2B1 | B7: Funded recovery, efficient diagnostics | C7: £30m — expanded recovery funding | D7: 1.25 — efficient conversion | E7: 30000000 | F7: 1.25
A8: A2B2 | B8: Funded recovery, test-heavy pathways | C8: £30m — expanded recovery funding | D8: 3.50 — test-heavy pathways | E8: 30000000 | F8: 3.5
A9: BASE | B9: Central case (reference) | C9: central | D9: central | E9: 15000000 | F9: 1.75
A11: Scenarios are not weighted by probability. In the intuitive-logics tradition they test plausibility, and a strategy that only works in the scenario judged most likely is precisely the failure mode the method exists to catch.

Sheet Strategies
A1: Stage 3: Candidate Strategies
A2: Each strategy is a commitment expressed as a constraint set over the same linear programme, so all are evaluated on identical terms. The last three columns are analyst judgement, not computation.
A4: Code | B4: Strategy | C4: What it commits to | D4: Why it is on the list | E4: Flexible (1-5) | F4: Insurable (1-5) | G4: Institutional feasibility
A5: S0 | B5: Hold position | C5: Commit no additional recovery funding. The backlog follows its business-as-usual trajectory. | D5: Included because a do-nothing baseline is the only way to state what the other strategies buy. In wayfinding terms this is the practical-coping trajectory the ICB is already on. | E5: 5 | F5: 5 | G5: High legitimacy risk. Regulator and public expectation is visible action on 52-week waits; inaction is not a defensible position even where it is affordable.
A6: S1 | B6: Unconstrained optimisation | C6: Allocate the full envelope wherever the model says it clears the most breaches, with the standing 15pp equity tolerance. | D6: The Phase 3 answer, carried forward unchanged so that the value of every added constraint can be read off against it. | E6: 3 | F6: 2 | G6: Moderate risk. An allocation that changes shape whenever an input is revised is difficult to defend to provider boards, who experience it as arbitrary.
A7: S2 | B7: NHS delivery only | C7: Deliver recovery entirely through NHS providers — in-house treatment capacity or diagnostic capacity. No independent-sector outsourcing. | D7: Tests the position that recovery money should build durable NHS capability rather than buy activity that leaves no residue. | E7: 2 | F7: 2 | G7: High legitimacy within the provider field; aligns with professional and staff-side expectations about where recovery money should go.
A8: S3 | B8: No in-house expansion | C8: Deliver recovery by buying independent-sector activity and by unlocking diagnostics. No expansion of in-house treatment capacity. | D8: Tests the opposite position: fastest access to activity, no long-term cost base. | E8: 5 | F8: 4 | G8: Contested. Independent-sector reliance is politically sensitive within the NHS field and attracts staff-side objection even where it performs.
A9: S4 | B9: Diagnostic-led recovery | C9: Direct at least half the envelope to diagnostic capacity, on the basis that diagnostics gate the pathway. | D9: Tests whether unlocking the diagnostic constraint clears more pathways per pound than adding treatment capacity directly. | E9: 3 | F9: 2 | G9: Strong legitimacy — matches the national diagnostic-capacity policy direction and is readily explained to boards.
A10: S5 | B10: Equity-first | C10: Require higher-deprivation providers to receive at least their baseline share of the breaches cleared. No equity tolerance. | D10: Tests the cost of removing the 15pp tolerance and holding a hard proportionality floor instead. | E10: 3 | F10: 2 | G10: Strong legitimacy. Directly answers the statutory duty to reduce inequalities in access and is straightforward to evidence.
A11: S7 | B11: Treatment capacity only | C11: Fund treatment capacity — in-house or independent sector — and nothing through the diagnostic lever. | D11: The counterpart to S4, and the strategy that prices the diagnostic bet. Because the diagnostic lever rests entirely on the one unsourced parameter in the model, this shows what the programme delivers if that assumption is set aside altogether. | E11: 3 | F11: 3 | G11: Low risk but low ambition. Treats the diagnostic constraint as fixed, which sits awkwardly against national policy emphasis on diagnostic capacity.
A12: S6 | B12: Diversified hedge | C12: Cap any single lever at 50% of spend, so the programme is never more than half exposed to one delivery assumption. | D12: Constructed against the Ch.8 principle that keeping options open beats optimising to a single expected case when the key inputs are weakly evidenced. | E12: 4 | F12: 3 | G12: Defensible. Spreads exposure across the competing positions in the field rather than adjudicating between them.
A14: Flexible and insurable follow Wright and Goodwin (2009), reported in Cairns and Wright (2018) Ch.8: is the commitment scalable up or down once made, and can its downside be capped contractually. Institutional feasibility follows Sminia (2022) Ch.7. An allocation that violates the legitimacy expectations of the NHS field will not be enacted however well it scores, so it is screened separately rather than blended into the same weighted total.

Sheet Results grid
A1: Strategy x Scenario Results
A2: Every cell is a separate solve of the same linear programme. Blue figures come from the solver; black figures are derived here.
A4: Scenario | B4: Strategy | C4: Name | D4: Breaches cleared | E4: Cleared in higher-deprivation trusts | F4: Equity share | G4: Total cost | H4: Breaches per £1m | I4: Delivery-risk exposure | J4: Share of baseline cleared
A5: A1B1 | B5: S0 | C5: Hold position | D5: 0 | E5: 0 | F5: =IF(D5=0,0,E5/D5) -> 0 | G5: 0 | H5: =IF(G5=0,0,ROUND(D5/(G5/1000000),1)) -> 0 | I5: 0 | J5: 0
A6: A1B1 | B6: S1 | C6: Unconstrained optimisation | D6: 42454 | E6: 42454 | F6: =IF(D6=0,0,E6/D6) -> 1 | G6: 7500000 | H6: =IF(G6=0,0,ROUND(D6/(G6/1000000),1)) -> 5660.5 | I6: 1 | J6: 0.14328911
A7: A1B1 | B7: S2 | C7: NHS delivery only | D7: 42454 | E7: 42454 | F7: =IF(D7=0,0,E7/D7) -> 1 | G7: 7500000 | H7: =IF(G7=0,0,ROUND(D7/(G7/1000000),1)) -> 5660.5 | I7: 1 | J7: 0.14328911
A8: A1B1 | B8: S3 | C8: No in-house expansion | D8: 42454 | E8: 42454 | F8: =IF(D8=0,0,E8/D8) -> 1 | G8: 7499992.5 | H8: =IF(G8=0,0,ROUND(D8/(G8/1000000),1)) -> 5660.5 | I8: 1 | J8: 0.14328911
A9: A1B1 | B9: S4 | C9: Diagnostic-led recovery | D9: 42454 | E9: 42454 | F9: =IF(D9=0,0,E9/D9) -> 1 | G9: 7500000 | H9: =IF(G9=0,0,ROUND(D9/(G9/1000000),1)) -> 5660.5 | I9: 1 | J9: 0.14328911
A10: A1B1 | B10: S5 | C10: Equity-first | D10: 42454 | E10: 42454 | F10: =IF(D10=0,0,E10/D10) -> 1 | G10: 7500000 | H10: =IF(G10=0,0,ROUND(D10/(G10/1000000),1)) -> 5660.5 | I10: 1 | J10: 0.14328911
A11: A1B1 | B11: S7 | C11: Treatment capacity only | D11: 15873 | E11: 15873 | F11: =IF(D11=0,0,E11/D11) -> 1 | G11: 7500000 | H11: =IF(G11=0,0,ROUND(D11/(G11/1000000),1)) -> 2116.4 | I11: 0 | J11: 0.053574833
A12: A1B1 | B12: S6 | C12: Diversified hedge | D12: 29164 | E12: 29164 | F12: =IF(D12=0,0,E12/D12) -> 1 | G12: 7500000 | H12: =IF(G12=0,0,ROUND(D12/(G12/1000000),1)) -> 3888.5 | I12: 0.7279 | J12: 0.098431945
A13: A1B2 | B13: S0 | C13: Hold position | D13: 0 | E13: 0 | F13: =IF(D13=0,0,E13/D13) -> 0 | G13: 0 | H13: =IF(G13=0,0,ROUND(D13/(G13/1000000),1)) -> 0 | I13: 0 | J13: 0
A14: A1B2 | B14: S1 | C14: Unconstrained optimisation | D14: 15873 | E14: 15873 | F14: =IF(D14=0,0,E14/D14) -> 1 | G14: 7499992.5 | H14: =IF(G14=0,0,ROUND(D14/(G14/1000000),1)) -> 2116.4 | I14: 0 | J14: 0.05357478
A15: A1B2 | B15: S2 | C15: NHS delivery only | D15: 15873 | E15: 15873 | F15: =IF(D15=0,0,E15/D15) -> 1 | G15: 7499992.5 | H15: =IF(G15=0,0,ROUND(D15/(G15/1000000),1)) -> 2116.4 | I15: 0 | J15: 0.05357478
A16: A1B2 | B16: S3 | C16: No in-house expansion | D16: 15873 | E16: 15873 | F16: =IF(D16=0,0,E16/D16) -> 1 | G16: 7500000 | H16: =IF(G16=0,0,ROUND(D16/(G16/1000000),1)) -> 2116.4 | I16: 1 | J16: 0.05357478
... A44: BASE | B44: S6 | C44: Diversified hedge | D44: 46198 | E44: 46198 | F44: =IF(D44=0,0,E44/D44) -> 1 | G44: 15000000 | H44: =IF(G44=0,0,ROUND(D44/(G44/1000000),1)) -> 3079.9 | I44: 0.6564 | J44: 0.15592414

Sheet Decision analysis
A1: Ch.5 Sum-of-Ranks Decision Analysis
A2: Every strategy-scenario combination is ranked against every other on each objective, and the ranks are summed per strategy. Lower total is better. Change the weights in the yellow cells and the ordering recalculates.
A4: Objective weights
A5: Objective | B5: Direction | C5: Weight
A6: Breaches cleared | B6: maximise | C6: 1
A7: Cleared in higher-deprivation trusts | B7: maximise | C7: 1
A8: Breaches per £1m | B8: maximise | C8: 1
A9: Delivery-risk exposure | B9: minimise | C9: 1
A12: Scenario | B12: Strategy | C12: Rank: breaches | D12: Rank: equity | E12: Rank: value for money | F12: Rank: delivery risk | G12: Weighted sum
A13: ='Results grid'!A5 -> A1B1 | B13: ='Results grid'!B5 -> S0 | C13: =RANK('Results grid'!D5,'Results grid'!$D$5:$D$44,0) -> 36 | D13: =RANK('Results grid'!E5,'Results grid'!$E$5:$E$44,0) -> 36 | E13: =RANK('Results grid'!H5,'Results grid'!$H$5:$H$44,0) -> 36 | F13: =RANK('Results grid'!I5,'Results grid'!$I$5:$I$44,1) -> 1 | G13: =C13*$C$6+D13*$C$7+E13*$C$8+F13*$C$9 -> 109
A14: ='Results grid'!A6 -> A1B1 | B14: ='Results grid'!B6 -> S1 | C14: =RANK('Results grid'!D6,'Results grid'!$D$5:$D$44,0) -> 21 | D14: =RANK('Results grid'!E6,'Results grid'!$E$5:$E$44,0) -> 20 | E14: =RANK('Results grid'!H6,'Results grid'!$H$5:$H$44,0) -> 6 | F14: =RANK('Results grid'!I6,'Results grid'!$I$5:$I$44,1) -> 24 | G14: =C14*$C$6+D14*$C$7+E14*$C$8+F14*$C$9 -> 71
A15: ='Results grid'!A7 -> A1B1 | B15: ='Results grid'!B7 -> S2 | C15: =RANK('Results grid'!D7,'Results grid'!$D$5:$D$44,0) -> 21 | D15: =RANK('Results grid'!E7,'Results grid'!$E$5:$E$44,0) -> 20 | E15: =RANK('Results grid'!H7,'Results grid'!$H$5:$H$44,0) -> 6 | F15: =RANK('Results grid'!I7,'Results grid'!$I$5:$I$44,1) -> 24 | G15: =C15*$C$6+D15*$C$7+E15*$C$8+F15*$C$9 -> 71
A16: ='Results grid'!A8 -> A1B1 | B16: ='Results grid'!B8 -> S3 | C16: =RANK('Results grid'!D8,'Results grid'!$D$5:$D$44,0) -> 21 | D16: =RANK('Results grid'!E8,'Results grid'!$E$5:$E$44,0) -> 20 | E16: =RANK('Results grid'!H8,'Results grid'!$H$5:$H$44,0) -> 6 | F16: =RANK('Results grid'!I8,'Results grid'!$I$5:$I$44,1) -> 24 | G16: =C16*$C$6+D16*$C$7+E16*$C$8+F16*$C$9 -> 71
A17: ='Results grid'!A9 -> A1B1 | B17: ='Results grid'!B9 -> S4 | C17: =RANK('Results grid'!D9,'Results grid'!$D$5:$D$44,0) -> 21 | D17: =RANK('Results grid'!E9,'Results grid'!$E$5:$E$44,0) -> 20 | E17: =RANK('Results grid'!H9,'Results grid'!$H$5:$H$44,0) -> 6 | F17: =RANK('Results grid'!I9,'Results grid'!$I$5:$I$44,1) -> 24 | G17: =C17*$C$6+D17*$C$7+E17*$C$8+F17*$C$9 -> 71
A18: ='Results grid'!A10 -> A1B1 | B18: ='Results grid'!B10 -> S5 | C18: =RANK('Results grid'!D10,'Results grid'!$D$5:$D$44,0) -> 21 | D18: =RANK('Results grid'!E10,'Results grid'!$E$5:$E$44,0) -> 20 | E18: =RANK('Results grid'!H10,'Results grid'!$H$5:$H$44,0) -> 6 | F18: =RANK('Results grid'!I10,'Results grid'!$I$5:$I$44,1) -> 24 | G18: =C18*$C$6+D18*$C$7+E18*$C$8+F18*$C$9 -> 71
A19: ='Results grid'!A11 -> A1B1 | B19: ='Results grid'!B11 -> S7 | C19: =RANK('Results grid'!D11,'Results grid'!$D$5:$D$44,0) -> 28 | D19: =RANK('Results grid'!E11,'Results grid'!$E$5:$E$44,0) -> 28 | E19: =RANK('Results grid'!H11,'Results grid'!$H$5:$H$44,0) -> 20 | F19: =RANK('Results grid'!I11,'Results grid'!$I$5:$I$44,1) -> 1 | G19: =C19*$C$6+D19*$C$7+E19*$C$8+F19*$C$9 -> 77
A20: ='Results grid'!A12 -> A1B1 | B20: ='Results grid'!B12 -> S6 | C20: =RANK('Results grid'!D12,'Results grid'!$D$5:$D$44,0) -> 27 | D20: =RANK('Results grid'!E12,'Results grid'!$E$5:$E$44,0) -> 27 | E20: =RANK('Results grid'!H12,'Results grid'!$H$5:$H$44,0) -> 16 | F20: =RANK('Results grid'!I12,'Results grid'!$I$5:$I$44,1) -> 22 | G20: =C20*$C$6+D20*$C$7+E20*$C$8+F20*$C$9 -> 92
A21: ='Results grid'!A13 -> A1B2 | B21: ='Results grid'!B13 -> S0 | C21: =RANK('Results grid'!D13,'Results grid'!$D$5:$D$44,0) -> 36 | D21: =RANK('Results grid'!E13,'Results grid'!$E$5:$E$44,0) -> 36 | E21: =RANK('Results grid'!H13,'Results grid'!$H$5:$H$44,0) -> 36 | F21: =RANK('Results grid'!I13,'Results grid'!$I$5:$I$44,1) -> 1 | G21: =C21*$C$6+D21*$C$7+E21*$C$8+F21*$C$9 -> 109
A22: ='Results grid'!A14 -> A1B2 | B22: ='Results grid'!B14 -> S1 | C22: =RANK('Results grid'!D14,'Results grid'!$D$5:$D$44,0) -> 28 | D22: =RANK('Results grid'!E14,'Results grid'!$E$5:$E$44,0) -> 28 | E22: =RANK('Results grid'!H14,'Results grid'!$H$5:$H$44,0) -> 20 | F22: =RANK('Results grid'!I14,'Results grid'!$I$5:$I$44,1) -> 1 | G22: =C22*$C$6+D22*$C$7+E22*$C$8+F22*$C$9 -> 77
A23: ='Results grid'!A15 -> A1B2 | B23: ='Results grid'!B15 -> S2 | C23: =RANK('Results grid'!D15,'Results grid'!$D$5:$D$44,0) -> 28 | D23: =RANK('Results grid'!E15,'Results grid'!$E$5:$E$44,0) -> 28 | E23: =RANK('Results grid'!H15,'Results grid'!$H$5:$H$44,0) -> 20 | F23: =RANK('Results grid'!I15,'Results grid'!$I$5:$I$44,1) -> 1 | G23: =C23*$C$6+D23*$C$7+E23*$C$8+F23*$C$9 -> 77
A24: ='Results grid'!A16 -> A1B2 | B24: ='Results grid'!B16 -> S3 | C24: =RANK('Results grid'!D16,'Results grid'!$D$5:$D$44,0) -> 28 | D24: =RANK('Results grid'!E16,'Results grid'!$E$5:$E$44,0) -> 28 | E24: =RANK('Results grid'!H16,'Results grid'!$H$5:$H$44,0) -> 20 | F24: =RANK('Results grid'!I16,'Results grid'!$I$5:$I$44,1) -> 24 | G24: =C24*$C$6+D24*$C$7+E24*$C$8+F24*$C$9 -> 100
... A52: ='Results grid'!A44 -> BASE | B52: ='Results grid'!B44 -> S6 | C52: =RANK('Results grid'!D44,'Results grid'!$D$5:$D$44,0) -> 20 | D52: =RANK('Results grid'!E44,'Results grid'!$E$5:$E$44,0) -> 19 | E52: =RANK('Results grid'!H44,'Results grid'!$H$5:$H$44,0) -> 18 | F52: =RANK('Results grid'!I44,'Results grid'!$I$5:$I$44,1) -> 21 | G52: =C52*$C$6+D52*$C$7+E52*$C$8+F52*$C$9 -> 78
A54: Total by strategy (lower is better)
A55: Strategy | B55: Name | C55: Sum of ranks | D55: Ordering
A56: S0 | B56: Hold position | C56: =SUMIF($B$13:$B$52,A56,$G$13:$G$52) -> 545 | D56: =RANK(C56,$C$56:$C$63,1) -> 8
A57: S1 | B57: Unconstrained optimisation | C57: =SUMIF($B$13:$B$52,A57,$G$13:$G$52) -> 274 | D57: =RANK(C57,$C$56:$C$63,1) -> 1
A58: S2 | B58: NHS delivery only | C58: =SUMIF($B$13:$B$52,A58,$G$13:$G$52) -> 274 | D58: =RANK(C58,$C$56:$C$63,1) -> 1
A59: S3 | B59: No in-house expansion | C59: =SUMIF($B$13:$B$52,A59,$G$13:$G$52) -> 339 | D59: =RANK(C59,$C$56:$C$63,1) -> 5
A60: S4 | B60: Diagnostic-led recovery | C60: =SUMIF($B$13:$B$52,A60,$G$13:$G$52) -> 361 | D60: =RANK(C60,$C$56:$C$63,1) -> 6
A61: S5 | B61: Equity-first | C61: =SUMIF($B$13:$B$52,A61,$G$13:$G$52) -> 274 | D61: =RANK(C61,$C$56:$C$63,1) -> 1
A62: S7 | B62: Treatment capacity only | C62: =SUMIF($B$13:$B$52,A62,$G$13:$G$52) -> 295 | D62: =RANK(C62,$C$56:$C$63,1) -> 4
A63: S6 | B63: Diversified hedge | C63: =SUMIF($B$13:$B$52,A63,$G$13:$G$52) -> 374 | D63: =RANK(C63,$C$56:$C$63,1) -> 7
A66: Weight sensitivity: does the ordering survive a different priority?
A67: Weighting tested | B67: Resulting order, best to worst
A68: Equal weights (as set above) | B68: S1 > S2 > S5 > S7 > S3 > S4 > S6 > S0
A69: breaches cleared x2 | B69: S1 > S2 > S5 > S7 > S3 > S4 > S6 > S0
A70: breaches cleared x3 | B70: S1 > S2 > S5 > S3 > S7 > S4 > S6 > S0
A71: breaches cleared higher deprivation x2 | B71: S1 > S2 > S5 > S7 > S3 > S4 > S6 > S0
A72: breaches cleared higher deprivation x3 | B72: S1 > S2 > S5 > S7 > S3 > S4 > S6 > S0
A73: breaches per million x2 | B73: S1 > S2 > S5 > S7 > S3 > S4 > S6 > S0
...

Sheet Regret
A1: Ch.8 Minimax Regret
A2: Regret is the breaches a strategy gives up, in a given scenario, against the best that could have been done in that scenario. A minimax-regret strategy is the one whose worst case across scenarios is least bad.
A4: Strategy | B4: Name | C4: Regret: A1B1 | D4: Regret: A1B2 | E4: Regret: A2B1 | F4: Regret: A2B2 | G4: Regret: BASE | H4: Worst-case regret
A5: S0 | B5: Hold position | C5: 42454 | D5: 15873 | E5: 169817 | F5: 63493 | G5: 60649 | H5: =MAX(C5:G5) -> 169817
A6: S1 | B6: Unconstrained optimisation | C6: 0 | D6: 0 | E6: 0 | F6: 0 | G6: 0 | H6: =MAX(C6:G6) -> 0
A7: S2 | B7: NHS delivery only | C7: 0 | D7: 0 | E7: 0 | F7: 0 | G7: 0 | H7: =MAX(C7:G7) -> 0
A8: S3 | B8: No in-house expansion | C8: 0 | D8: 0 | E8: 0 | F8: 0 | G8: 0 | H8: =MAX(C8:G8) -> 0
A9: S4 | B9: Diagnostic-led recovery | C9: 0 | D9: 355 | E9: 0 | F9: 1422 | G9: 0 | H9: =MAX(C9:G9) -> 1422
A10: S5 | B10: Equity-first | C10: 0 | D10: 0 | E10: 0 | F10: 0 | G10: 0 | H10: =MAX(C10:G10) -> 0
A11: S7 | B11: Treatment capacity only | C11: 26581 | D11: 0 | E11: 106324 | F11: 0 | G11: 28902 | H11: =MAX(C11:G11) -> 106324
A12: S6 | B12: Diversified hedge | C12: 13290 | D12: 0 | E12: 53162 | F12: 0 | G12: 14451 | H12: =MAX(C12:G12) -> 53162
A14: Read alongside the sum-of-ranks table rather than instead of it. Minimax regret looks only at breaches cleared and is indifferent to equity, value for money and delivery risk; several strategies tie at effectively zero regret because they reach the same volume by different routes. It is the tie-break, not the decision.

Sheet Early warning
A1: Ch.8 Early-Warning Flags
A2: What to measure each month to know which scenario is actually arriving. Restricted to quantities the warehouse holds; where none exists, the gap is stated rather than filled with a proxy.
A4: Flag | B4: Factor | C4: Indicator | D4: Source | E4: Current value | F4: Trigger | G4: Action if triggered
A5: F1 | B5: Funding settlement (Factor A) | C5: Confirmed elective recovery envelope for the ICB, 18 months to Sep-2027 | D5: NOT IN WAREHOUSE — NHS England allocation and planning guidance; ICB finance ledger | E5: not observable from warehouse | F5: Envelope confirmed below £10m, or above £25m | G5: Re-run the grid at the confirmed envelope. This is the highest-impact uncertainty in the model and the only one with no internal data source, so it must be tracked through the finance route rather than the analytics one.
A6: F2 | B6: Diagnostic conversion (Factor B) | C6: DM01 diagnostic tests per completed RTT pathway, 12 core trusts, monthly | D6: fact_dm01_provider_month.total_activity / fact_rtt_provider_specialty_month.completed_pathways_total | E6: 0.84 (trailing 12 months); 0.76 across full window | F6: Sustained rise above 2.00 for three consecutive months triggers review; 3.34 is the point at which the optimal strategy changes shape entirely | G6: Above the tipping point the diagnostic lever is no longer the cheapest route to a cleared pathway and the programme should shift to treatment capacity. The observed proxy currently sits well below both thresholds.
A7: F3 | B7: Diagnostic capacity headroom | C7: Share of the DM01 diagnostic waiting list waiting over six weeks | D7: fact_dm01_provider_month.waiting_list_over_6wk / waiting_list_size | E7: 10.2% mean over the last 12 months, against 8.1% over the preceding 12 | F7: A statistically significant upward trend sustained over two quarters, or the 12-month mean exceeding 15% | G7: The model assumes 10% headroom for additional diagnostic activity, so a deteriorating diagnostic waiting list would undercut the recommended strategy at source. Read the level, not the last data point: over the full window the series trends significantly DOWNWARD (-0.001 points per month, p=0.009), and over the last 24 months there is no significant trend either way (p=0.21) on a series with a standard deviation of about 2 points. The 12-month mean has stepped up by roughly 2 points, which is worth watching but is not evidence of deterioration.
A8: F4 | B8: Backlog trajectory | C8: ICB total RTT waiting list against the Monte Carlo forecast band | D8: fact_rtt_provider_specialty_month vs fact_rtt_waitinglist_forecast_provider_month | E8: 686,298 at Mar-2026; over-52-week waits 7,836 | F8: Actual outside the p5–p95 band for two consecutive months | G8: Recalibrate the forecast. Note that backlog size has no effect on the optimal allocation at any funding level in scope — the budget clears far less than the backlog either way — so this flag governs the credibility of the stated ambition, not the choice of strategy.
A9: F5 | B9: Independent-sector capacity | C9: Independent-sector NHS-funded completed pathways, trailing six-month mean | D9: fact_rtt_provider_specialty_month, independent-sector providers | E9: 7,510 per month | F9: Dormant below a £31.9m envelope | G9: The independent-sector capacity ceiling does not bind until the envelope exceeds £31.9m, above the top of the scenario range. Monitoring is not warranted at current funding levels and is recorded here so that the omission is deliberate rather than overlooked.
A10: F6 | B10: NHS in-house capacity | C10: General and acute bed headroom (KH03) and consultant FTE | D10: fact_kh03_provider_quarter, fact_workforce_provider_year | E10: tracked in the Phase 3 model inputs | F10: Dormant below a £107.1m envelope | G10: As F5. The in-house capacity ceiling is an order of magnitude beyond any funding level under consideration and cannot bind.

Sheet Diagnostic triangulation
A1: Closing the Last Unsourced Parameter
A2: The diagnostic lever is priced on an assumed 1.75 tests per unlocked pathway, with no published source. This tab tests that assumption against observed activity.
A4: Model assumption (tests per unlocked pathway) | B4: 1.75 | C4: Analyst estimate carried since Phase 3. No NHS dataset publishes this ratio.
A5: Tipping point, strategy changes above this | B5: 3.343 | C5: Computed by bisection. Above this value the diagnostic lever is dominated by treatment capacity and the recommended strategy changes.
A6: Observed, trailing 12 months | B6: 0.839 | C6: DM01 total diagnostic activity divided by completed RTT pathways, 12 core trusts.
A7: Observed, full window | B7: 0.764 | C7: Across 84 months of data.
A8: Observed minimum | B8: 0.604 | C8: Lowest single month in the window.
A9: Observed maximum | B9: 0.913 | C9: Highest single month. The observed ratio has never reached even half the tipping point.
A11: Why this does not settle the parameter
A12: • | B12: DM01 covers 15 test types and no pathology, so it understates total diagnostic input per pathway.
A13: • | B13: Not every DM01 test sits on an RTT pathway, so it overstates the tests attributable to RTT completions.
A14: • | B14: The model parameter is marginal (tests to unlock one additional pathway); this proxy is an average across all activity. They are different quantities.
A15: • | B15: The two measurement biases run in opposite directions and neither is quantified, so no net correction is applied or implied.
A17: Conclusion
A18: The proxy does not settle the parameter and is not presented as doing so. It does establish that the observed DM01-to-completion ratio has never in 84 months of data approached the 3.34 level at which the recommended strategy would change. The direction of the recommendation is therefore better evidenced than the magnitude of the benefit it produces.

Sheet Recommendation
A1: Recommendation
A2: For the Elective Recovery Programme Board
B4: Recommendation | C4: Commit to S2, NHS delivery only. Deliver the elective recovery programme entirely through NHS providers, weighted to diagnostic capacity while the conversion ratio holds, with no independent-sector outsourcing.
B5: Why this one, and what the model does and does not settle | C5: The analysis narrows the field to three commitments that are numerically identical: S1 unconstrained optimisation, S2 NHS delivery only, and S5 equity-first produce the same result on every objective in every scenario. Neither the outsourcing lock nor the equity floor binds, so the model is genuinely indifferent between them and cannot pick one. The tie is therefore broken on the ground the model does not capture: institutional legitimacy. Of the three, S2 is the most defensible to provider boards and staff side, and commits to nothing the other two would not also do.
B6: The one real trade-off | C6: S7, treatment capacity only, is the genuine alternative. It never touches the two levers whose capacity assumptions are unsourced, so it carries zero delivery-risk exposure in every scenario, and it takes first place whenever delivery risk is weighted at twice or three times the other objectives. It matches S2 on volume in two of the four scenarios. But where diagnostics are efficient it gives up a great deal: 26,581 fewer breaches cleared in the lean-money case and 106,324 fewer in the funded case. Choosing between S2 and S7 is a judgement about risk appetite, not a calculation, and the Board should make it as one.
B7: What the analysis rules out | C7: Three questions that have absorbed attention are not live decisions at these funding levels. Independent-sector scalability, NHS in-house productivity and the size of the backlog itself change the outcome by nothing, because no capacity ceiling binds below a £31.9m envelope. Within the range under consideration this is a money-constrained problem, not a capacity-constrained one.
B8: What the decision actually turns on | C8: One number: how many diagnostic tests it takes to unlock one additional completed pathway. Below 3.34, diagnostics are the cheapest route and the programme should be diagnostic-led. Above it, the programme should buy treatment capacity instead. The working assumption is 1.75. Observed DM01 activity per completed pathway is 0.84 and has never exceeded 0.92 in 84 months, well clear of the threshold, though the observed ratio is an average and the parameter is a marginal one, so it bounds the argument rather than settling it.
B9: The equity finding | C9: The equity tolerance in the Phase 3 model never binds. At every funding level examined, the entire reduction can be directed to higher-deprivation providers at no cost whatsoever to total breaches cleared, because the budget clears far less than those trusts alone are carrying. Equity here is not a trade-off to be managed. It is free, and the programme should be designed to take it.
B10: What would change this view | C10: Flag F2: the diagnostic conversion ratio rising above 2.00 for three consecutive months warrants review, and above 3.34 reverses the lever choice. Flag F3: the share of the diagnostic waiting list waiting over six weeks averaged 10.2% over the last twelve months against 8.1% over the preceding twelve. That step up is worth watching, because the recommended strategy assumes 10% headroom for additional diagnostic activity, but it should not be overstated. Over the full window the series trends significantly downward, and over the last 24 months there is no significant trend in either direction. Flag F1: the funding envelope is the single highest-impact uncertainty in the model and has no internal data source. It must be tracked through the finance route.
B11: Where the model stops | C11: Every strategy examined here is a different way of allocating a budget across three levers that already exist. At the funding levels in scope the best of them clears roughly a fifth of the projected over-52-week backlog. If the objective is to clear the backlog rather than to reduce it, no allocation of this envelope across these levers reaches that, and the question stops being an optimisation problem. That is a different kind of problem from the one this model solves, and it should be named as such rather than answered with a better-tuned version of the same answer.
